<?xml version="1.0" ?>
<robot name="aerotrain">
  <joint name="imu_joint" type="fixed">
    <parent link="base_link"/>
    <child link="imu_link"/>
    <origin xyz="0  0  0.5" rpy="0 0 0"/>
    <axis xyz="1 0 0"/>
    <limit lower="0.0" upper="0.0" effort="0.0" velocity="0.0"/>
  </joint>
  <joint name="rotor_3_joint" type="revolute">
    <parent link="base_link"/>
    <child link="rotor_3"/>
    <origin xyz="-0.2979 -0.172   0.52" rpy="0 0 0"/>
    <axis xyz="0 0 1"/>
    <limit lower="-1e+16" upper="1e+16" effort="10.0" velocity="-1.0"/>
  </joint>
  <joint name="rotor_0_joint" type="revolute">
    <parent link="base_link"/>
    <child link="rotor_0"/>
    <origin xyz="0    -0.344  0.52" rpy="0 0 0"/>
    <axis xyz="0 0 1"/>
    <limit lower="-1e+16" upper="1e+16" effort="10.0" velocity="-1.0"/>
  </joint>
  <joint name="rotor_4_joint" type="revolute">
    <parent link="base_link"/>
    <child link="rotor_4"/>
    <origin xyz="0.2979 -0.172   0.52" rpy="0 0 0"/>
    <axis xyz="0 0 1"/>
    <limit lower="-1e+16" upper="1e+16" effort="10.0" velocity="-1.0"/>
  </joint>
  <joint name="rotor_1_joint" type="revolute">
    <parent link="base_link"/>
    <child link="rotor_1"/>
    <origin xyz="0    0.344 0.52" rpy="0 0 0"/>
    <axis xyz="0 0 1"/>
    <limit lower="-1e+16" upper="1e+16" effort="10.0" velocity="-1.0"/>
  </joint>
  <joint name="rotor_5_joint" type="revolute">
    <parent link="base_link"/>
    <child link="rotor_5"/>
    <origin xyz="-0.2979  0.172   0.52" rpy="0 0 0"/>
    <axis xyz="0 0 1"/>
    <limit lower="-1e+16" upper="1e+16" effort="10.0" velocity="-1.0"/>
  </joint>
  <joint name="rotor_2_joint" type="revolute">
    <parent link="base_link"/>
    <child link="rotor_2"/>
    <origin xyz="0.2979 0.172  0.52" rpy="0 0 0"/>
    <axis xyz="0 0 1"/>
    <limit lower="-1e+16" upper="1e+16" effort="10.0" velocity="-1.0"/>
  </joint>
  <joint name="gps_joint" type="fixed">
    <parent link="base_link"/>
    <child link="gps__link"/>
    <origin xyz="0  0  0.5" rpy="0 0 0"/>
    <axis xyz="0 0 0"/>
    <limit lower="0" upper="0" effort="0" velocity="0"/>
  </joint>
  <joint name="camera_joint" type="fixed">
    <parent link="base_link"/>
    <child link="camera_link"/>
    <origin xyz="0.2  0  0.52" rpy="-1.57 0 -1.57"/>
    <axis xyz="0 0 0"/>
    <limit lower="0" upper="0" effort="0" velocity="0"/>
  </joint>
  <joint name="rplidar_joint" type="fixed">
    <parent link="base_link"/>
    <child link="rplidar_link"/>
    <origin xyz="0.0  0  0.05" rpy="0 0 0"/>
    <axis xyz="0 0 0"/>
    <limit lower="0" upper="0" effort="0" velocity="0"/>
  </joint>
  <link name="base_link">
    <inertial>
      <mass value="4.0"/>
      <origin xyz="0    0   -0.01" rpy="0 0 0"/>
      <inertia ixx="0.022" ixy="0" ixz="0" iyy="0.030" iyz="0" izz="0.042"/>
    </inertial>
    <collision name="base_link_collision">
      <origin xyz="0  0  0.4" rpy="0 0 0"/>
      <geometry>
        <box size="0.25 0.25 0.28"/>
      </geometry>
    </collision>
    <visual name="base_link_visual">
      <origin xyz="0  0  0.5" rpy="0 0 0"/>
      <geometry>
        <mesh filename="package://PATHTOMESHES/meshes/tarot680.obj" scale="1 1 1"/>
      </geometry>
    </visual>
  </link>
  <link name="imu_link">
    <inertial>
      <mass value="0.015"/>
      <origin xyz="0 0 0" rpy="0 0 0"/>
      <inertia ixx="1e-05" ixy="0" ixz="0" iyy="1e-05" iyz="0" izz="1e-05"/>
    </inertial>
  </link>
  <link name="rotor_3">
    <inertial>
      <mass value="0.005"/>
      <origin xyz="0 0 0" rpy="0 0 0"/>
      <inertia ixx="9.75e-07" ixy="0" ixz="0" iyy="0.000273104" iyz="0" izz="0.000274004"/>
    </inertial>
    <collision name="rotor_3_collision">
      <origin xyz="0 0 0" rpy="0 0 0"/>
      <geometry>
        <cylinder radius="0.165" length="0.005"/>
      </geometry>
    </collision>
    <visual name="rotor_3_visual">
      <origin xyz="0 0 0" rpy="0 0 0"/>
      <geometry>
        <mesh filename="package://PATHTOMESHES/meshes/ccw_prop.obj" scale="1 1 1"/>
      </geometry>
    </visual>
  </link>
  <link name="rotor_0">
    <inertial>
      <mass value="0.005"/>
      <origin xyz="0 0 0" rpy="0 0 0"/>
      <inertia ixx="9.75e-07" ixy="0" ixz="0" iyy="0.000273104" iyz="0" izz="0.000274004"/>
    </inertial>
    <collision name="rotor_0_collision">
      <origin xyz="0 0 0" rpy="0 0 0"/>
      <geometry>
        <cylinder radius="0.165" length="0.005"/>
      </geometry>
    </collision>
    <visual name="rotor_0_visual">
      <origin xyz="0 0 0" rpy="0 0 0"/>
      <geometry>
        <mesh filename="package://PATHTOMESHES/meshes/cw_prop.obj" scale="1 1 1"/>
      </geometry>
    </visual>
  </link>
  <link name="rotor_4">
    <inertial>
      <mass value="0.005"/>
      <origin xyz="0 0 0" rpy="0 0 0"/>
      <inertia ixx="9.75e-07" ixy="0" ixz="0" iyy="0.000273104" iyz="0" izz="0.000274004"/>
    </inertial>
    <collision name="rotor_4_collision">
      <origin xyz="0 0 0" rpy="0 0 0"/>
      <geometry>
        <cylinder radius="0.165" length="0.005"/>
      </geometry>
    </collision>
    <visual name="rotor_4_visual">
      <origin xyz="0 0 0" rpy="0 0 0"/>
      <geometry>
        <mesh filename="package://PATHTOMESHES/meshes/ccw_prop.obj" scale="1 1 1"/>
      </geometry>
    </visual>
  </link>
  <link name="rotor_1">
    <inertial>
      <mass value="0.005"/>
      <origin xyz="0 0 0" rpy="0 0 0"/>
      <inertia ixx="9.75e-07" ixy="0" ixz="0" iyy="0.000273104" iyz="0" izz="0.000274004"/>
    </inertial>
    <collision name="rotor_1_collision">
      <origin xyz="0 0 0" rpy="0 0 0"/>
      <geometry>
        <cylinder radius="0.165" length="0.005"/>
      </geometry>
    </collision>
    <visual name="rotor_1_visual">
      <origin xyz="0 0 0" rpy="0 0 0"/>
      <geometry>
        <mesh filename="package://PATHTOMESHES/meshes/ccw_prop.obj" scale="1 1 1"/>
      </geometry>
    </visual>
  </link>
  <link name="rotor_5">
    <inertial>
      <mass value="0.005"/>
      <origin xyz="0 0 0" rpy="0 0 0"/>
      <inertia ixx="9.75e-07" ixy="0" ixz="0" iyy="0.000273104" iyz="0" izz="0.000274004"/>
    </inertial>
    <collision name="rotor_5_collision">
      <origin xyz="0 0 0" rpy="0 0 0"/>
      <geometry>
        <cylinder radius="0.165" length="0.005"/>
      </geometry>
    </collision>
    <visual name="rotor_5_visual">
      <origin xyz="0 0 0" rpy="0 0 0"/>
      <geometry>
        <mesh filename="package://PATHTOMESHES/meshes/cw_prop.obj" scale="1 1 1"/>
      </geometry>
    </visual>
  </link>
  <link name="rotor_2">
    <inertial>
      <mass value="0.005"/>
      <origin xyz="0 0 0" rpy="0 0 0"/>
      <inertia ixx="9.75e-07" ixy="0" ixz="0" iyy="0.000273104" iyz="0" izz="0.000274004"/>
    </inertial>
    <collision name="rotor_2_collision">
      <origin xyz="0 0 0" rpy="0 0 0"/>
      <geometry>
        <cylinder radius="0.165" length="0.005"/>
      </geometry>
    </collision>
    <visual name="rotor_2_visual">
      <origin xyz="0 0 0" rpy="0 0 0"/>
      <geometry>
        <mesh filename="package://PATHTOMESHES/meshes/cw_prop.obj" scale="1 1 1"/>
      </geometry>
    </visual>
  </link>
  <link name="gps__link">
    <inertial>
      <mass value="0.015"/>
      <origin xyz="0 0 0" rpy="0 0 0"/>
      <inertia ixx="1e-05" ixy="0" ixz="0" iyy="1e-05" iyz="0" izz="1e-05"/>
    </inertial>
    <visual name="gps__visual">
      <origin xyz="0 0 0" rpy="0 0 0"/>
      <geometry>
        <cylinder radius="0.01" length="0.002"/>
      </geometry>
    </visual>
  </link>
</robot>
